Workbook
Name MY_FUNCTION1: LAMBDA(VALUE(MID(MID('Form responses 1'!$C$2,FIND("query=",'Form responses 1'!$C$2)+6,50),FIND("%2C",MID('Form responses 1'!$C$2,FIND("query=",'Form responses 1'!$C$2)+6,50))+3,50)))

Sheet Form responses 1
A1: Timestamp | B1: STORE NAME AND CONTACT PERSON | C1: PHONE NUMBER | D1: TIME | E1: PHOTOGRAPH | F1: TOBACCO PRODUCTS INTERESTED IN/THEY DEAL IN | G1: ORDER DETAILS IF CONVERTED | H1: CLICK THE LINK TO RECORD LOCATION. DID YOU RECORD THE LOCATION? | I1: STORE CATEGORY | J1: SR NAME | K1: REMARKS | L1: LEAD TYPE | M1: FOLLOW UP DATE | N1: STORE VISIT TYPE | O1: DATE | P1: ADMIN REMARKS | Q1: LATITUDE | R1: LONGITUDE
H2: YES | I2: HoReca | Q2: =IFERROR(VLOOKUP(#REF!,'Location Sheet'!C:G,4,FALSE),"") | R2: =IFERROR(VLOOKUP(#REF!,'LOCATION RESPONSES'!B:G,7,FALSE),"")
A3: 46002.611 | B3: Family supar market/ram pukar mahatu/R | C3: 8826049990 | D3: 0.61458333 | E3: https://drive.google.com/open?id=1LLp0DhHFSv7YQ9mS4SaARmc3ViSWnT60 | F3: CIGARETTE | G3: No ordar owner is not available | H3: YES | I3: MT
A4: 46002.627 | B4: Plu meriya mart/subol debnaght/R | C4: 7896424507 | D4: 0.62361111 | E4: https://drive.google.com/open?id=1XxQSaNs1isYtF8bjHlTzO59tX9fN8dRC | F4: CIGARETTE, CIGARS | G4: No ordar | H4: YES | I4: MT
A7: 46002.635 | B7: O Guwahati/Skar | C7: 8472050051 | D7: 0.62361111 | E7: https://drive.google.com/open?id=1K_ZdZpR9_1SY8AClbNjUhK6jInFJnPMM | F7: CIGARETTE | G7: They don't keep | H7: YES | I7: HoReca
A8: 46002.638 | B8: Quick shop/somita dey/R | C8: 6002195040 | D8: 0.63611111 | E8: https://drive.google.com/open?id=1Hl2DtrDuQfO4An7IkgEN6z7RaffCNzfK | F8: CIGARETTE | G8: No sell chegaret | H8: YES | I8: MT
A9: 46002.638 | B9: O Guwahati | C9: 9954746951 | D9: 0.13611111 | E9: https://drive.google.com/open?id=1xPSy6Vj5sNXQJAEnGrf9XxL_NNL2whbf | F9: CIGARETTE | G9: They do jot keep but has smoking area | H9: YES | I9: HoReca
A10: 46002.644 | B10: Ann agero/jintu boro/R | C10: 6003795097 | D10: 0.64305556 | E10: https://drive.google.com/open?id=1XGznTqBh5fTreux3oClMvKYXcwKeSI9P | F10: CIGARETTE | G10: Not sell chegaret | H10: YES | I10: MT
A11: 46002.648 | B11: Olive Garden/Skar | C11: 9619320927 | D11: 0.14583333 | E11: https://drive.google.com/open?id=1ZN-dd8iexg3Gd75xR0jMd1H8YTgfDnpy | F11: HOOKAH | G11: No cigarette | H11: YES | I11: HoReca
A12: 46002.661 | B12: Assam quick santer/sambhu naght shing/ | C12: 9706221712 | D12: 0.65972222 | E12: https://drive.google.com/open?id=1FEh-9zgkO8z8ONeGNoIGM44FeGx_JwjI | F12: CIGARETTE | G12: Not sell chegaret | H12: YES | I12: MT
A13: 46002.671 | B13: Socialite/Skar | C13: 9702506770 | D13: 0.66666667 | E13: https://drive.google.com/open?id=18qSe5Wd3HacYtFgVRcZ7gnT8NLu5KdCF | F13: HOOKAH | H13: YES | I13: HoReca
A14: 46002.698 | B14: Scottish House | C14: 9859578173 | D14: 0.68263889 | E14: https://drive.google.com/open?id=10XfVTRORZw61BCgQb8mR7czbgSuTvY9Q | F14: ZIPPO LIGHTERS | G14: They do not keep | H14: YES | I14: HoReca
A15: 46002.7 | B15: Kitchen n bar | C15: 843896453 | D15: 0.69861111 | E15: https://drive.google.com/open?id=1oXC-4xKmzVSR6iZy1Gz55hbq9A_neuDW | F15: ROLLING PAPERS | G15: They don't keep | H15: YES | I15: HoReca
A16: 46002.703 | B16: Smart pic/rajandra shing/R | C16: 9365423205 | D16: 0.70138889 | E16: https://drive.google.com/open?id=1-ZWZIzDWPkxbSnZrBHX_1W5iI1CRM6bj | F16: CIGARETTE | G16: Not selling chegaret | H16: YES | I16: MT
A17: 46002.704 | B17: Ascend/Skar | C17: 6003885766 | D17: 0.20277778 | E17: https://drive.google.com/open?id=1-6TUbVYhlowiGEiteCwuaIooBsIilLWm | F17: CIGARETTE, HOOKAH | G17: Box with samples | H17: YES | I17: HoReca
A18: 46002.711 | B18: Prince supar market/pranob juti deka/R | C18: 9435116686 | D18: 0.71111111 | E18: https://drive.google.com/open?id=1ZYjf2n4Kn9kREPlbMAtIGcBZWjJsasDQ | F18: CIGARETTE | G18: No menejar | H18: YES | I18: MT
A19: 46002.761 | B19: Attic/ Tushar | C19: 9435400105 | D19: 0.75347222 | E19: https://drive.google.com/open?id=13Af-bcQSIXCme07ywunPWbMdyqCsJRZV | F19: HOOKAH | H19: YES | I19: HoReca | J19: SHUBRAM KAR
A20: 46002.77 | B20: Gateway Grandeur | C20: 737084860 | D20: 0.76736111 | E20: https://drive.google.com/open?id=1_0KTZeommgOKVm8pNxYP-0KOHsxpFeah | F20: ZIPPO LIGHTERS | H20: YES | I20: HoReca | J20: SHUBRAM KAR
A21: 46002.782 | B21: Arista/ Deborshi | C21: 9903935859 | D21: 0.78055556 | E21: https://drive.google.com/open?id=1WLzjPxK7KhuMtAO0UJc94Q3WQGEIXnSI | F21: HOOKAH | G21: Later | H21: YES | I21: HoReca | J21: SHUBRAM KAR
A22: 46003.574 | B22: Gharana enterpris/yogesh | C22: 9864066993y | E22: https://drive.google.com/open?id=1T1kV2VivNuxpNXIYHtDvgc3FsBvKYNsM | F22: NONE | G22: No order | H22: YES | I22: MT | J22: RAJU DAS | K22: Not sell chegaret and tabacou | L22: WARM | Q22: =COUNTIF('LOCATION RESPONSES'!B:B,B2) -> 0 | R22: =COUNTIF('LOCATION RESPONSES'!B:B,B2) -> 0
A23: 46003.597 | B23: Bishnujyoti stor /shuru kumar das | C23: 7638039088 | E23: https://drive.google.com/open?id=1IclQVGyqTFw-V6xZxjP09tpV9XtwHsLF | F23: CIGARETTE | G23: No ordar | H23: YES | I23: MT | J23: RAJU DAS | K23: Will ordar next month | L23: COLD | Q23: =COUNTIF('LOCATION RESPONSES'!B:B,B3) -> 0 | R23: =COUNTIF('LOCATION RESPONSES'!B:B,B3) -> 0
A24: 46003.607 | B24: Maa kamakhya agency/sanjy kumar | C24: 9706076848 | E24: https://drive.google.com/open?id=1F5HixGtaFKm_ADIujFIQ16Eh0hE8FRfX | F24: CIGARETTE | G24: No | H24: YES | I24: MT | J24: RAJU DAS | K24: Not entered the product | L24: COLD | Q24: =COUNTIF('LOCATION RESPONSES'!B:B,B4) -> 0 | R24: =COUNTIF('LOCATION RESPONSES'!B:B,B4) -> 0
A25: 46003.619 | B25: Quality shoppe/asifh husain | C25: 7099073999 | E25: https://drive.google.com/open?id=1YGm5DSmNj9WAvo5lXrxoWsHdy30VGlaM | F25: CIGARETTE | G25: No | H25: YES | I25: MT | J25: RAJU DAS | K25: Menejar not available talk tomorrow | L25: COLD | Q25: =COUNTIF('LOCATION RESPONSES'!B:B,B5) -> 0 | R25: =COUNTIF('LOCATION RESPONSES'!B:B,B5) -> 0
A26: 46003.647 | B26: Fresh busket/miton husain | C26: 7002708344 | E26: https://drive.google.com/open?id=1RUyk28ONy7EvArvjWB3UQbH_A05e4HOY | F26: NONE | G26: No | H26: YES | I26: MT | J26: RAJU DAS | K26: Talk next week | Q26: =COUNTIF('LOCATION RESPONSES'!B:B,B6) -> 0 | R26: =COUNTIF('LOCATION RESPONSES'!B:B,B6) -> 0
A27: 46003.671 | B27: Pariwar supar market /shidgart | C27: 8638376372 | E27: https://drive.google.com/open?id=1UA8IlWLa5iz0Jzmw9hMUMGbenr_hJ2yW | F27: CIGARETTE | G27: No | H27: YES | I27: MT | J27: RAJU DAS | K27: Next week oedar | L27: COLD | Q27: =COUNTIF('LOCATION RESPONSES'!B:B,B7) -> 0 | R27: =COUNTIF('LOCATION RESPONSES'!B:B,B7) -> 0
A28: 46003.682 | B28: The grocer supar market/ganesh nagun | C28: 6000392311 | E28: https://drive.google.com/open?id=1qlg6Dc_oOiI16_0vWyjKC7vVXX__7jAH | F28: NONE | G28: No | H28: YES | I28: MT | J28: RAJU DAS | K28: That dont want sell chegaret | L28: DEAD | Q28: =COUNTIF('LOCATION RESPONSES'!B:B,B8) -> 0 | R28: =COUNTIF('LOCATION RESPONSES'!B:B,B8) -> 0
A29: 46003.696 | B29: Niharika enterprise/nilomoni bhoiso | C29: 847395657 | E29: https://drive.google.com/open?id=1Fy9KqsNY1x1lyyRzI-kdSWrsd6-5_90H | F29: CIGARETTE | G29: No | H29: YES | I29: MT | J29: RAJU DAS | K29: Will talk manday | L29: COLD | Q29: =IFERROR(VLOOKUP(B9,'LOCATION RESPONSES'!B:G,6,FALSE),"") -> 91.783491 | R29: =COUNTIF('LOCATION RESPONSES'!B:B,B9) -> 1
A30: 46003.705 | B30: S K stor / nipon joyti das | C30: 9864273182 | E30: https://drive.google.com/open?id=1eEjwbMn7kTLxzPMsqDOgYREfXoICASgF | F30: NONE | G30: No | H30: YES | I30: MT | J30: RAJU DAS | K30: Not sell chegaret | L30: DEAD | Q30: =COUNTIF('LOCATION RESPONSES'!B:B,B8) -> 0 | R30: =COUNTIF('LOCATION RESPONSES'!B:B,B10) -> 0
A31: 46003.715 | B31: Suniya stor/sofiqul islam | C31: 6901422045 | E31: https://drive.google.com/open?id=1HW9QE-xNLvUu-6g9cViqtcbx-qkMVQrz | F31: CIGARETTE | G31: No | H31: YES | I31: MT | J31: RAJU DAS | K31: This shop is holselar but baba company all redy give him the proud t | L31: COLD | Q31: =COUNTIF('LOCATION RESPONSES'!B:B,B9) -> 1 | R31: =COUNTIF('LOCATION RESPONSES'!B:B,B11) -> 0
A32: 46004.541 | B32: Nayantara supar market/sujit jain | C32: 7099574158 | E32: https://drive.google.com/open?id=1ckLnj7jhUKxCKhOm5gEvKrETFsIRaauQ | F32: ZIPPO LIGHTERS | G32: No | H32: YES | I32: MT | J32: RAJU DAS | K32: Not sell chegaret | L32: COLD | Q32: =COUNTIF('LOCATION RESPONSES'!B:B,B10) -> 0 | R32: =COUNTIF('LOCATION RESPONSES'!B:B,B12) -> 0
A33: 46004.549 | B33: Spicy cake and sweets/raju sir | C33: 7002796908 | E33: https://drive.google.com/open?id=1sorDQ2m7Mhz9SuKPgg0EhhPLpPu4jfFH | F33: NONE | G33: No | H33: YES | I33: MT | J33: RAJU DAS | K33: Not sell | L33: WARM | Q33: =COUNTIF('LOCATION RESPONSES'!B:B,B11) -> 0 | R33: =COUNTIF('LOCATION RESPONSES'!B:B,B13) -> 0
A34: 46004.557 | B34: Naima stor/mohomd ali | C34: 9678140533 | E34: https://drive.google.com/open?id=1JP3rpUAIGZgOl5U_Tcil4GUymNxcaDud | F34: CIGARETTE | H34: YES | I34: MT | J34: RAJU DAS | K34: No oedar talk next month | L34: COLD | Q34: =COUNTIF('LOCATION RESPONSES'!B:B,B12) -> 0 | R34: =COUNTIF('LOCATION RESPONSES'!B:B,B14) -> 0
A35: 46004.57 | B35: Balaji bhandar/kahanaiya lal | C35: 8133950037 | E35: https://drive.google.com/open?id=1RV842zYL2juigfj4TUge2RnAj5e1q8Lo | F35: CIGARETTE | G35: No | H35: YES | I35: MT | J35: RAJU DAS | K35: Don't want to sell | L35: COLD | Q35: =COUNTIF('LOCATION RESPONSES'!B:B,B13) -> 0 | R35: =COUNTIF('LOCATION RESPONSES'!B:B,B15) -> 0
A36: 46004.572 | B36: Mollah stor/mahibul ali | C36: 6003769243 | E36: https://drive.google.com/open?id=1J3MGKB1wp-UFzA4lYempcNMKPVtGDAiP | F36: CIGARETTE | G36: No | H36: YES | I36: MT | J36: RAJU DAS | K36: Not gd response | L36: COLD | Q36: =COUNTIF('LOCATION RESPONSES'!B:B,B14) -> 0 | R36: =COUNTIF('LOCATION RESPONSES'!B:B,B16) -> 0
A37: 46004.589 | B37: Urmi suparmarket/beraj gupta | C37: 8011708006 | E37: https://drive.google.com/open?id=1Yy2SFGeGehB_nnctUo5L_HJQe6JZ5dTj | F37: CIGARETTE | G37: No | H37: YES | I37: MT | J37: RAJU DAS | K37: Will talk next week | L37: COLD | Q37: =COUNTIF('LOCATION RESPONSES'!B:B,B15) -> 0 | R37: =COUNTIF('LOCATION RESPONSES'!B:B,B17) -> 0
A38: 46004.594 | B38: Anopurna stor /arjun | C38: 9957720094 | E38: https://drive.google.com/open?id=1aefrZoHf3QmojbV8sQ6D2fOqg_b3CjTt | F38: NONE | G38: No | H38: YES | I38: MT | J38: RAJU DAS | K38: Not sell chegaret | L38: DEAD | Q38: =COUNTIF('LOCATION RESPONSES'!B:B,B16) -> 0 | R38: =COUNTIF('LOCATION RESPONSES'!B:B,B18) -> 0
A39: 46004.598 | B39: Ganpati fresh dairy/ jintu bornon | C39: 9864872312 | E39: https://drive.google.com/open?id=18SqwwJnXrad-hGixwszvuoLGGHyI2e_c | F39: CIGARETTE | G39: No | H39: YES | I39: MT | J39: RAJU DAS | K39: Talk next week menejar not available | L39: COLD | Q39: =COUNTIF('LOCATION RESPONSES'!B:B,B17) -> 0 | R39: =COUNTIF('LOCATION RESPONSES'!B:B,B19) -> 0
A40: 46004.634 | B40: Babu bhander/bipul kumar medhi | C40: 7035571722 | E40: https://drive.google.com/open?id=1P4sE7Lw225eIvaYBsVcCTdyArfkUO3xz | F40: CIGARETTE | G40: No | H40: YES | I40: MT | J40: RAJU DAS | K40: No shop keeper | L40: COLD | Q40: =IFERROR(VLOOKUP(B20,'LOCATION RESPONSES'!B:G,6,FALSE),"") -> 91.775268 | R40: =COUNTIF('LOCATION RESPONSES'!B:B,B20) -> 1
A41: 46004.64 | B41: Krishna stor/himanshu sinha | C41: 9678226097 | E41: https://drive.google.com/open?id=1XYVjMXRG9yv6b5tfCAoVblWTiV_pCPON | F41: CIGARETTE | G41: No | H41: YES | I41: MT | J41: RAJU DAS | K41: Next week talk | L41: COLD | Q41: =COUNTIF('LOCATION RESPONSES'!B:B,B14) -> 0 | R41: =COUNTIF('LOCATION RESPONSES'!B:B,B21) -> 0
A42: 46004.658 | B42: Handique artist home /prosato handique | C42: 8811961568 | E42: https://drive.google.com/open?id=1mKbjGtXFYYxBzdwnHXUUqoVZp0Rmdh2g | F42: CIGARETTE | G42: No | H42: YES | I42: MT | J42: RAJU DAS | K42: No woner at shop | L42: COLD | Q42: =COUNTIF('LOCATION RESPONSES'!B:B,B15) -> 0 | R42: =COUNTIF('LOCATION RESPONSES'!B:B,B22) -> 0
...

Sheet LOCATION RESPONSES
A1: Timestamp | B1: Store Name | C1: Location | D1: Accuracy (m) | E1: ExtraInfo | F1: LATITUDE | G1: LONGITUDE
A2: 46002.61 | B2: Family super market | C2: https://www.google.com/maps/search/?api=1&query=26.143083%2C91.8122021 | D2: 22.584999 | E2: Mozilla/5.0 (Linux; Android 10; K) AppleWebKit/537.36 (KHTML, like Gecko) Chrome/144.0.0.0 Mobile Safari/537.36 | F2: =VALUE(LEFT(MID(C2,FIND("query=",C2)+6,50),FIND("%2C",MID(C2,FIND("query=",C2)+6,50))-1)) -> 26.143083 | G2: =VALUE(MID(MID(C2,FIND("query=",C2)+6,50),FIND("%2C",MID(C2,FIND("query=",C2)+6,50))+3,50)) -> 91.812202
A3: 46002.625 | B3: Pull Mary mart | C3: https://www.google.com/maps/search/?api=1&query=26.133466%2C91.8317512 | D3: 13.623 | E3: Mozilla/5.0 (Linux; Android 10; K) AppleWebKit/537.36 (KHTML, like Gecko) Chrome/144.0.0.0 Mobile Safari/537.36 | F3: =VALUE(LEFT(MID(C3,FIND("query=",C3)+6,50),FIND("%2C",MID(C3,FIND("query=",C3)+6,50))-1)) -> 26.133466 | G3: =VALUE(MID(MID(C3,FIND("query=",C3)+6,50),FIND("%2C",MID(C3,FIND("query=",C3)+6,50))+3,50)) -> 91.831751
A4: 46002.63 | B4: Kieko | C4: https://www.google.com/maps/search/?api=1&query=26.156065%2C91.78065 | D4: 19.719 | E4: Mozilla/5.0 (Linux; Android 10; K) AppleWebKit/537.36 (KHTML, like Gecko) Chrome/131.0.0.0 Mobile Safari/537.36 | F4: =VALUE(LEFT(MID(C4,FIND("query=",C4)+6,50),FIND("%2C",MID(C4,FIND("query=",C4)+6,50))-1)) -> 26.156065 | G4: =VALUE(MID(MID(C4,FIND("query=",C4)+6,50),FIND("%2C",MID(C4,FIND("query=",C4)+6,50))+3,50)) -> 91.78065
A5: 46002.637 | B5: O Guwahati | C5: https://www.google.com/maps/search/?api=1&query=26.1508814%2C91.7834907 | D5: 12.628 | E5: Mozilla/5.0 (Linux; Android 10; K) AppleWebKit/537.36 (KHTML, like Gecko) Chrome/131.0.0.0 Mobile Safari/537.36 | F5: =VALUE(LEFT(MID(C5,FIND("query=",C5)+6,50),FIND("%2C",MID(C5,FIND("query=",C5)+6,50))-1)) -> 26.150881 | G5: =VALUE(MID(MID(C5,FIND("query=",C5)+6,50),FIND("%2C",MID(C5,FIND("query=",C5)+6,50))+3,50)) -> 91.783491
A6: 46002.638 | B6: Quick shop | C6: https://www.google.com/maps/search/?api=1&query=26.13301%2C91.8298416 | D6: 11.516 | E6: Mozilla/5.0 (Linux; Android 10; K) AppleWebKit/537.36 (KHTML, like Gecko) Chrome/144.0.0.0 Mobile Safari/537.36 | F6: =VALUE(LEFT(MID(C6,FIND("query=",C6)+6,50),FIND("%2C",MID(C6,FIND("query=",C6)+6,50))-1)) -> 26.13301 | G6: =VALUE(MID(MID(C6,FIND("query=",C6)+6,50),FIND("%2C",MID(C6,FIND("query=",C6)+6,50))+3,50)) -> 91.829842
A7: 46002.644 | B7: Ann negruli | C7: https://www.google.com/maps/search/?api=1&query=26.1327564%2C91.8166271 | D7: 12.986 | E7: Mozilla/5.0 (Linux; Android 10; K) AppleWebKit/537.36 (KHTML, like Gecko) Chrome/144.0.0.0 Mobile Safari/537.36 | F7: =VALUE(LEFT(MID(C7,FIND("query=",C7)+6,50),FIND("%2C",MID(C7,FIND("query=",C7)+6,50))-1)) -> 26.132756 | G7: =VALUE(MID(MID(C7,FIND("query=",C7)+6,50),FIND("%2C",MID(C7,FIND("query=",C7)+6,50))+3,50)) -> 91.816627
A8: 46002.647 | B8: Olive Garden | C8: https://www.google.com/maps/search/?api=1&query=26.1523644%2C91.7811835 | D8: 20 | E8: Mozilla/5.0 (Linux; Android 10; K) AppleWebKit/537.36 (KHTML, like Gecko) Chrome/131.0.0.0 Mobile Safari/537.36 | F8: =VALUE(LEFT(MID(C8,FIND("query=",C8)+6,50),FIND("%2C",MID(C8,FIND("query=",C8)+6,50))-1)) -> 26.152364 | G8: =VALUE(MID(MID(C8,FIND("query=",C8)+6,50),FIND("%2C",MID(C8,FIND("query=",C8)+6,50))+3,50)) -> 91.781183
A9: 46002.661 | B9: Assam quick shop | C9: https://www.google.com/maps/search/?api=1&query=26.1056177%2C91.8545398 | D9: 56.099998 | E9: Mozilla/5.0 (Linux; Android 10; K) AppleWebKit/537.36 (KHTML, like Gecko) Chrome/144.0.0.0 Mobile Safari/537.36 | F9: =VALUE(LEFT(MID(C9,FIND("query=",C9)+6,50),FIND("%2C",MID(C9,FIND("query=",C9)+6,50))-1)) -> 26.105618 | G9: =VALUE(MID(MID(C9,FIND("query=",C9)+6,50),FIND("%2C",MID(C9,FIND("query=",C9)+6,50))+3,50)) -> 91.85454
A10: 46002.671 | B10: Socialite | C10: https://www.google.com/maps/search/?api=1&query=26.1535208%2C91.7803735 | D10: 11.463 | E10: Mozilla/5.0 (Linux; Android 10; K) AppleWebKit/537.36 (KHTML, like Gecko) Chrome/131.0.0.0 Mobile Safari/537.36 | F10: =VALUE(LEFT(MID(C10,FIND("query=",C10)+6,50),FIND("%2C",MID(C10,FIND("query=",C10)+6,50))-1)) -> 26.153521 | G10: =VALUE(MID(MID(C10,FIND("query=",C10)+6,50),FIND("%2C",MID(C10,FIND("query=",C10)+6,50))+3,50)) -> 91.780373
A11: 46002.683 | B11: Pragati Manor | C11: https://www.google.com/maps/search/?api=1&query=26.1544501%2C91.7792302 | D11: 23.886999 | E11: Mozilla/5.0 (Linux; Android 10; K) AppleWebKit/537.36 (KHTML, like Gecko) Chrome/131.0.0.0 Mobile Safari/537.36 | F11: =VALUE(LEFT(MID(C11,FIND("query=",C11)+6,50),FIND("%2C",MID(C11,FIND("query=",C11)+6,50))-1)) -> 26.15445 | G11: =VALUE(MID(MID(C11,FIND("query=",C11)+6,50),FIND("%2C",MID(C11,FIND("query=",C11)+6,50))+3,50)) -> 91.77923
A12: 46002.7 | B12: Kitchen and bar | C12: https://www.google.com/maps/search/?api=1&query=26.1549427%2C91.7794864 | D12: 30.915001 | E12: Mozilla/5.0 (Linux; Android 10; K) AppleWebKit/537.36 (KHTML, like Gecko) Chrome/131.0.0.0 Mobile Safari/537.36 | F12: =VALUE(LEFT(MID(C12,FIND("query=",C12)+6,50),FIND("%2C",MID(C12,FIND("query=",C12)+6,50))-1)) -> 26.154943 | G12: =VALUE(MID(MID(C12,FIND("query=",C12)+6,50),FIND("%2C",MID(C12,FIND("query=",C12)+6,50))+3,50)) -> 91.779486
A13: 46002.703 | B13: Smart pic | C13: https://www.google.com/maps/search/?api=1&query=26.1261353%2C91.7974032 | D13: 22.527 | E13: Mozilla/5.0 (Linux; Android 10; K) AppleWebKit/537.36 (KHTML, like Gecko) Chrome/144.0.0.0 Mobile Safari/537.36 | F13: =VALUE(LEFT(MID(C13,FIND("query=",C13)+6,50),FIND("%2C",MID(C13,FIND("query=",C13)+6,50))-1)) -> 26.126135 | G13: =VALUE(MID(MID(C13,FIND("query=",C13)+6,50),FIND("%2C",MID(C13,FIND("query=",C13)+6,50))+3,50)) -> 91.797403
... A150: 46016.668 | B150: Zoo road shopping corner | C150: https://www.google.com/maps/search/?api=1&query=26.1779038%2C91.7757161 | D150: 19.721001 | E150: Mozilla/5.0 (Linux; Android 10; K) AppleWebKit/537.36 (KHTML, like Gecko) Chrome/144.0.0.0 Mobile Safari/537.36 | F150: =VALUE(LEFT(MID(C150,FIND("query=",C150)+6,50),FIND("%2C",MID(C150,FIND("query=",C150)+6,50))-1)) -> 26.177904 | G150: =VALUE(MID(MID(C150,FIND("query=",C150)+6,50),FIND("%2C",MID(C150,FIND("query=",C150)+6,50))+3,50)) -> 91.775716
A151: 46016.746 | B151: D S bhandar | C151: https://www.google.com/maps/search/?api=1&query=26.1744056%2C91.7769113 | D151: 12.384 | E151: Mozilla/5.0 (Linux; Android 10; K) AppleWebKit/537.36 (KHTML, like Gecko) Chrome/144.0.0.0 Mobile Safari/537.36
A152: 46018.495 | B152: Shree kanha's grocery | C152: https://www.google.com/maps/search/?api=1&query=26.1709282%2C91.7554801 | D152: 17.348 | E152: Mozilla/5.0 (Linux; Android 10; K) AppleWebKit/537.36 (KHTML, like Gecko) Chrome/144.0.0.0 Mobile Safari/537.36
A153: 46018.498 | B153: M prasad store | C153: https://www.google.com/maps/search/?api=1&query=26.1709844%2C91.7555171 | D153: 19.768 | E153: Mozilla/5.0 (Linux; Android 10; K) AppleWebKit/537.36 (KHTML, like Gecko) Chrome/144.0.0.0 Mobile Safari/537.36
A154: 46018.509 | B154: Dayamoyee store | C154: https://www.google.com/maps/search/?api=1&query=26.1693782%2C91.7546054 | D154: 15.268 | E154: Mozilla/5.0 (Linux; Android 10; K) AppleWebKit/537.36 (KHTML, like Gecko) Chrome/144.0.0.0 Mobile Safari/537.36
A155: 46018.523 | B155: Paul brothers | C155: https://www.google.com/maps/search/?api=1&query=26.1680488%2C91.7464672 | D155: 16.576 | E155: Mozilla/5.0 (Linux; Android 10; K) AppleWebKit/537.36 (KHTML, like Gecko) Chrome/144.0.0.0 Mobile Safari/537.36
A156: 46018.529 | B156: Prashant pan bhandar | C156: https://www.google.com/maps/search/?api=1&query=26.1681013%2C91.746434 | D156: 23.375 | E156: Mozilla/5.0 (Linux; Android 10; K) AppleWebKit/537.36 (KHTML, like Gecko) Chrome/144.0.0.0 Mobile Safari/537.36
A157: 46018.541 | B157: Biswajit bhandar | C157: https://www.google.com/maps/search/?api=1&query=26.1584712%2C91.7346103 | D157: 18.466 | E157: Mozilla/5.0 (Linux; Android 10; K) AppleWebKit/537.36 (KHTML, like Gecko) Chrome/144.0.0.0 Mobile Safari/537.36
A158: 46018.545 | B158: Mangal murti varieties | C158: https://www.google.com/maps/search/?api=1&query=26.1576587%2C91.732802 | D158: 17.969 | E158: Mozilla/5.0 (Linux; Android 10; K) AppleWebKit/537.36 (KHTML, like Gecko) Chrome/144.0.0.0 Mobile Safari/537.36
A159: 46018.549 | B159: Bikash store | C159: https://www.google.com/maps/search/?api=1&query=26.1567253%2C91.7322437 | D159: 18.593 | E159: Mozilla/5.0 (Linux; Android 10; K) AppleWebKit/537.36 (KHTML, like Gecko) Chrome/144.0.0.0 Mobile Safari/537.36
A160: 46018.553 | B160: Dutta brothers | C160: https://www.google.com/maps/search/?api=1&query=26.1558207%2C91.731309 | D160: 11.677 | E160: Mozilla/5.0 (Linux; Android 10; K) AppleWebKit/537.36 (KHTML, like Gecko) Chrome/144.0.0.0 Mobile Safari/537.36
A161: 46018.557 | B161: Rashan haat | C161: https://www.google.com/maps/search/?api=1&query=26.1485778%2C91.7286477 | D161: 11.795 | E161: Mozilla/5.0 (Linux; Android 10; K) AppleWebKit/537.36 (KHTML, like Gecko) Chrome/144.0.0.0 Mobile Safari/537.36
A162: 46018.563 | B162: Barmon store | C162: https://www.google.com/maps/search/?api=1&query=26.1413952%2C91.725983 | D162: 8.9549999 | E162: Mozilla/5.0 (Linux; Android 10; K) AppleWebKit/537.36 (KHTML, like Gecko) Chrome/144.0.0.0 Mobile Safari/537.36
... A244: 46041.757 | B244: New store | C244: https://www.google.com/maps/search/?api=1&query=26.1498545%2C91.7715468 | D244: 48.686001 | E244: Mozilla/5.0 (Linux; Android 10; K) AppleWebKit/537.36 (KHTML, like Gecko) Chrome/144.0.0.0 Mobile Safari/537.36
